Workbook

Sheet 上海入项审批测算表 2603M
A1: 毛利率预测表
O2: 直接成本
D3: 入项信息 | N3: 转正月薪 | O3: 税费 | P3: 年终奖 | Q3: 社保 | R3: 公积金 | S3: 福利 | T3: 电脑折旧 | U3: 年假 | V3: 招聘成本 | W3: 资金成本 | X3: 其他成本 | Y3: 成本合计 | Z3: 毛利额 | AA3: 毛利率 | AB3: 项目性质 | AC3: 入项提示 | AD3: 薪资结算比 | AE3: 离职状态 | AF3: 离职日期 | AG3: 备注
A4: 所属部门 | B4: 对应销售 | C4: 对应交付 | D4: 姓名 | E4: 入职时间 | F4: 签署合同 | G4: 客户 | H4: 岗位 | I4: 回款周期 | J4: 职级 | K4: 参保地 | L4: 月报价 | M4: 月报价 （不含税） | N4: 月薪（元） | O4: 专票 | P4: 年终奖 | Q4: 最低基数 | R4: 最低基数 | S4: 平均成本 | T4: 公司承担填写 | U4: 公司承担 | V4: 自招 | W4: 公司承担 | X4: 公司承担 | Y4: 成本合计 | Z4: 毛利额 | AA4: 毛利率 | AB4: 项目性质 | AC4: 入项提示 | AD4: 薪资结算比 | AE4: 离职状态 | AF4: 离职日期 | AG4: 备注
A5: 事业一部 | B5: 陶声铖 | C5: 吴国阳 | D5: 李** | E5: *** | F5: 海橘外部 | G5: 龙旗 | H5: BSP驱动工程师 | I5: 季度 | J5: 中级 | K5: 武汉 | L5: 26500 | M5: =L5-O5 -> 24719.2 | N5: 15000 | O5: =L5*0.0672 -> 1780.8 | Q5: =IF($Q$4="不缴纳",0,VLOOKUP(K5,配置项!A:D,3,0)) -> 1207 | R5: =IF($R$4="不缴纳",0,VLOOKUP(K5,配置项!A:D,4,0)) -> 120 | S5: 200 | U5: =IF($U$4="公司承担",N5/21.75*5/12,0) -> 287.35632 | V5: {=IF($V$4="自招",VLOOKUP(J5&"-"&AB5,IF({1,0},配置项!$G$1:$G$15&"-"&配置项!$F$1:$F$15,配置项!$H$1:$H$15),2,0),0)} -> 750 | W5: =IF($W$4="公司承担",VLOOKUP(I5,配置项!J:K,2,0),0)*L5 -> 530 | Y5: =SUM($N5:$X5) -> 19875.156 | Z5: =$M5-$Y5 -> 4844.0437 | AA5: =$Z5/$M5 -> 0.1959628 | AB5: ITO | AD5: =N5/L5 -> 0.56603774
A6: 事业三部 | B6: 汤文杰 | C6: 方龙翔 | D6: 张** | E6: *** | F6: 海橘外部 | G6: 诗悦 | H6: camera tuning工程师 | I6: =VLOOKUP(G6,配置项!M:N,2,FALSE) -> 双月 | J6: 中级 | K6: 上海 | L6: 28350 | M6: =L6 -> 28350 | N6: 15000 | O6: =M6*0.0672 -> 1905.12 | Q6: =IF($Q$4="不缴纳",0,VLOOKUP(K6,配置项!A:D,3,0)) -> 1918 | R6: =IF($R$4="不缴纳",0,VLOOKUP(K6,配置项!A:D,4,0)) -> 135 | S6: 200 | U6: =IF($U$4="公司承担",N6/21.75*5/12,0) -> 287.35632 | V6: {=IF($V$4="自招",VLOOKUP(J6&"-"&AB6,IF({1,0},配置项!$G$1:$G$15&"-"&配置项!$F$1:$F$15,配置项!$H$1:$H$15),2,0),0)} -> 750 | W6: =IF($W$4="公司承担",VLOOKUP(I6,配置项!J:K,2,0),0)*L6 -> 283.5 | Y6: =SUM($N6:$X6) -> 20478.976 | Z6: =$M6-$Y6 -> 7871.0237 | AA6: =$Z6/$M6 -> 0.27763752 | AB6: ITO | AD6: =N6/L6 -> 0.52910053
A7: 事业六部 | B7: 陈搏 | C7: 聂岑楠 | D7: 苏** | E7: *** | F7: 上海海橘 | G7: 小米 | H7: 路测驾驶员 | I7: =VLOOKUP(G7,配置项!M:N,2,FALSE) -> 季度 | J7: 中级 | K7: 无 | L7: 6835.9824 | M7: =L7 -> 6835.9824 | N7: 4176 | O7: 459.37802 | Q7: =IF($Q$4="不缴纳",0,VLOOKUP(K7,配置项!A:D,3,0)) -> 0 | R7: =IF($R$4="不缴纳",0,VLOOKUP(K7,配置项!A:D,4,0)) -> 0 | S7: 200 | U7: =IF($U$4="公司承担",N7/21.75*5/12,0) -> 80 | V7: {=IF($V$4="自招",VLOOKUP(J7&"-"&AB7,IF({1,0},配置项!$G$1:$G$15&"-"&配置项!$F$1:$F$15,配置项!$H$1:$H$15),2,0),0)} -> 375 | W7: =IF($W$4="公司承担",VLOOKUP(I7,配置项!J:K,2,0),0)*L7 -> 136.71965 | Y7: =SUM($N7:$X7) -> 5427.0977 | Z7: =$M7-$Y7 -> 1408.8847 | AA7: =$Z7/$M7 -> 0.20609836 | AB7: BPO | AD7: =N7/L7 -> 0.61088513

Sheet 配置项
A1: 社保缴纳地 | B1: 不缴纳 | C1: 最低社保 | D1: 最低公积金 | F1: 项目性质 | G1: 级别 | H1: 招聘成本 | J1: 回款方式 | K1: 资金费率 | M1: 客户 | N1: 回款周期 | O1: 资金费率
A2: 上海 | B2: 0 | C2: 1918 | D2: 135 | F2: ITO | G2: 助理 | H2: 650 | J2: 月度 | K2: 0.005 | M2: 安硕 | N2: 半年度 | O2: 0.04
A3: 南京 | B3: 0 | C3: 1255.12 | D3: 199 | F3: ITO | G3: 初级 | H3: 650 | J3: 双月 | K3: 0.01 | M3: 禾苗 | N3: 季度 | O3: 0.02
A4: 宁波 | B4: 0 | C4: 1257 | D4: 125 | F4: ITO | G4: 中级 | H4: 750 | J4: 季度 | K4: 0.02 | M4: 吉利 | N4: 半年度 | O4: 0.04
A5: 北京 | B5: 0 | C5: 1898 | D5: 127 | F5: ITO | G5: 中高级 | H5: 750 | J5: 半年度 | K5: 0.04 | M5: 立讯 | N5: 季度 | O5: 0.02
A6: 深圳 | B6: 0 | C6: 1237 | D6: 126 | F6: ITO | G6: 高级 | H6: 750 | J6: 年度 | K6: 0.1 | M6: 龙旗 | N6: 双月 | O6: 0.01
A7: 东莞 | B7: 0 | C7: =1187-104+50 -> 1133 | D7: 110 | F7: ITO | G7: 资深 | H7: 750 | M7: 华勤 | N7: 季度 | O7: 0.02
A8: 常州 | B8: 0 | C8: =1398-125+50 -> 1323 | D8: 125 | F8: ITO | G8: 专家 | H8: 750 | M8: 宝马 | N8: 双月 | O8: 0.01
A9: 苏州 | B9: 0 | C9: =1625-387+50 -> 1288 | D9: 397 | F9: BPO | G9: 助理 | H9: 325 | M9: 京东方 | N9: 季度 | O9: 0.02
A10: 无锡 | B10: 0 | C10: =1253+50 -> 1303 | D10: 200 | F10: BPO | G10: 初级 | H10: 325 | M10: 美格 | N10: 季度 | O10: 0.02
A11: 西安 | B11: 0 | C11: 1148 | D11: 173 | F11: BPO | G11: 中级 | H11: 375 | M11: 中信信诚 | N11: 月度 | O11: 0.005
A12: 合肥 | B12: 0 | C12: =1124-116+50 -> 1058 | D12: 116 | F12: BPO | G12: 中高级 | H12: 375 | M12: 北京银行 | N12: 半年度 | O12: 0.04
A13: 武汉 | B13: 0 | C13: =1268-111+50 -> 1207 | D13: 120 | F13: BPO | G13: 高级 | H13: 375 | M13: 星思半导体 | N13: 双月 | O13: 0.01
A14: 长沙 | B14: 0 | C14: =1214-105+50 -> 1159 | D14: 105 | F14: BPO | G14: 资深 | H14: 375 | M14: 太平人寿 | N14: 月度 | O14: 0.005
A15: 大连 | B15: 0 | C15: =1304+50 -> 1354 | D15: 126 | F15: BPO | G15: 专家 | H15: 375 | M15: 四维图新 | N15: 半年度 | O15: 0.04
A16: 沈阳 | B16: 0 | C16: 1299.23 | D16: 179 | M16: 车联天下 | N16: 季度 | O16: 0.02
A17: 福州 | B17: 0 | C17: =1088+50 -> 1138 | D17: 110 | M17: 弋途科技 | N17: 半年度 | O17: 0.04
A18: 南昌 | B18: 0 | C18: =1138-130+50 -> 1058 | D18: 130 | M18: 奋达 | N18: 双月 | O18: 0.01
A19: 惠州 | B19: 0 | C19: 1123 | D19: 239 | M19: 萨摩耶 | N19: 季度 | O19: 0.02
A20: 温州 | B20: 0 | C20: =1220.9+59 -> 1279.9 | D20: 299 | M20: 中诺 | N20: 双月 | O20: 0.01
A21: 杭州 | B21: 0 | C21: 1371 | D21: 125 | M21: 中汽研 | N21: 半年度 | O21: 0.04
A22: 嘉兴 | B22: 0 | C22: =1287+50 -> 1337 | D22: 203 | M22: 证券信托 | N22: 季度 | O22: 0.02
A23: 保定 | B23: 0 | C23: =1384-242+50 -> 1192 | D23: 264 | M23: 海港人寿 | N23: 双月 | O23: 0.01
A24: 太原 | B24: 0 | C24: 1116 | D24: 108 | M24: 依图 | N24: 双月 | O24: 0.01
A25: 成都 | B25: 0 | C25: 1246 | D25: 117 | M25: 华域视觉 | N25: 半年度 | O25: 0.04
A26: 郑州 | B26: 0 | C26: =1142-168+50 -> 1024 | D26: 168 | M26: 电信天翼云 | N26: 季度 | O26: 0.02
A27: 昆明 | B27: 0 | C27: =1077.45+50 -> 1127.45 | D27: 100 | M27: 银联 | N27: 季度 | O27: 0.02
A28: 厦门 | B28: 0 | C28: =1049+50 -> 1099 | D28: 181 | M28: 祥承 | N28: 双月 | O28: 0.01
A29: 广州 | B29: 0 | C29: =1500-125+50 -> 1425 | D29: 125 | M29: 中保科联 | N29: 季度 | O29: 0.02
A30: 重庆 | B30: 0 | C30: =1320.71+50 -> 1370.71 | D30: 117 | M30: 车凌 | N30: 季度 | O30: 0.02
A31: 芜湖 | B31: 0 | C31: =1148-109+50 -> 1089 | D31: 109 | M31: 诗悦 | N31: 双月 | O31: 0.01
A32: 贵阳 | B32: 0 | C32: 1425 | D32: 107 | M32: 美年大健康 | N32: 双月 | O32: 0.01
A33: 泸州 | B33: 0 | C33: 1303.55 | D33: 99 | M33: 雄狮 | N33: 半年度 | O33: 0.04
A34: 龙岩 | B34: 0 | C34: 1070.5 | D34: 98 | M34: 厦门公安 | N34: 季度 | O34: 0.02
A35: 聊城 | B35: 0 | C35: =1118+50 -> 1168 | D35: 96 | M35: 灵伴智能 | N35: 双月 | O35: 0.01
A36: 天津 | B36: 0 | C36: =1636-162+50 -> 1524 | D36: 162 | M36: 魔视智能 | N36: 月度 | O36: 0.005
A37: 乌鲁木齐 | B37: 0 | C37: 1334.74 | D37: 85 | M37: 博泰 | N37: 季度 | O37: 0.02
A38: 衡阳 | B38: 0 | C38: =998+50 -> 1048 | D38: 287 | M38: 叠纸 | N38: 月度 | O38: 0.005
A39: 柳州 | B39: 0 | C39: =1200-176+50 -> 1074 | D39: 176 | M39: 袋鼠云 | N39: 季度 | O39: 0.02
A40: 青岛 | B40: 0 | C40: 1176.9 | D40: 110 | M40: 歌尔 | N40: 季度 | O40: 0.02
...
